[ WARN ] Failed to fetch value for field: Sym.Dev.SAP_connection
[ WARN ] Traceback (most recent call last):
  File "C:\RobotFramework\sap_testing\Execution\Access_Data.py", line 58, in get_data
    field_value = eval(command)
                  ^^^^^^^^^^^^^
  File "<string>", line 1, in <module>
AttributeError: module 'Data.Symphony.Dev' has no attribute 'SAP_connection'. Did you mean: 'sap_connection'?

[ WARN ] Failed to fetch value for field: Sym.Dev.SAP_connection
[ WARN ] Traceback (most recent call last):
  File "C:\RobotFramework\sap_testing\Tests\Resource\CustomSapGuiLibrary.py", line 485, in open_connection
    self.connection = self.sapapp.OpenConnection(connection_name, True)
                      ^^^^^^^^^^^^^^^^^^^^^^^^^^^^^^^^^^^^^^^^^^^^^^^^^
  File "<COMObject <unknown>>", line 2, in OpenConnection
pywintypes.com_error: (-2147352567, 'Exception occurred.', (1000, 'saplogon', 'SAP Logon connection entry not found', None, 0, 0), None)

During handling of the above exception, another exception occurred:

Traceback (most recent call last):
  File "C:\RobotFramework\sap_testing\Tests\Resource\CustomSapGuiLibrary.py", line 489, in open_connection
    raise ValueError(message)
ValueError: Cannot open connection '', please check connection name.

During handling of the above exception, another exception occurred:

Traceback (most recent call last):
  File "C:\RobotFramework\sap_testing\Execution\Access_Data.py", line 58, in get_data
    field_value = eval(command)
                  ^^^^^^^^^^^^^
  File "<string>", line 1, in <module>
AttributeError: module 'Data.Symphony.Dev' has no attribute 'SAP_connection'. Did you mean: 'sap_connection'?

[ WARN ] Failed to fetch value for field: Sym.Dev.connection
[ WARN ] Traceback (most recent call last):
  File "C:\RobotFramework\sap_testing\Execution\Access_Data.py", line 58, in get_data
    field_value = eval(command)
                  ^^^^^^^^^^^^^
  File "<string>", line 1, in <module>
AttributeError: module 'Data.Symphony.Dev' has no attribute 'connection'. Did you mean: 'sap_connection'?

[ WARN ] Failed to fetch value for field: Sym.Dev.connection
[ WARN ] Traceback (most recent call last):
  File "C:\RobotFramework\sap_testing\Tests\Resource\CustomSapGuiLibrary.py", line 485, in open_connection
    self.connection = self.sapapp.OpenConnection(connection_name, True)
                      ^^^^^^^^^^^^^^^^^^^^^^^^^^^^^^^^^^^^^^^^^^^^^^^^^
  File "<COMObject <unknown>>", line 2, in OpenConnection
pywintypes.com_error: (-2147352567, 'Exception occurred.', (1000, 'saplogon', 'SAP Logon connection entry not found', None, 0, 0), None)

During handling of the above exception, another exception occurred:

Traceback (most recent call last):
  File "C:\RobotFramework\sap_testing\Tests\Resource\CustomSapGuiLibrary.py", line 489, in open_connection
    raise ValueError(message)
ValueError: Cannot open connection '', please check connection name.

During handling of the above exception, another exception occurred:

Traceback (most recent call last):
  File "C:\RobotFramework\sap_testing\Execution\Access_Data.py", line 58, in get_data
    field_value = eval(command)
                  ^^^^^^^^^^^^^
  File "<string>", line 1, in <module>
AttributeError: module 'Data.Symphony.Dev' has no attribute 'connection'. Did you mean: 'sap_connection'?

[ WARN ] Failed to fetch value for field: Sym.Dev.connection
[ WARN ] Traceback (most recent call last):
  File "C:\RobotFramework\sap_testing\Execution\Access_Data.py", line 58, in get_data
    field_value = eval(command)
                  ^^^^^^^^^^^^^
  File "<string>", line 1, in <module>
AttributeError: module 'Data.Symphony.Dev' has no attribute 'connection'. Did you mean: 'sap_connection'?

[ WARN ] Failed to fetch value for field: Sym.Dev.connection
[ WARN ] Traceback (most recent call last):
  File "C:\RobotFramework\sap_testing\Tests\Resource\CustomSapGuiLibrary.py", line 485, in open_connection
    self.connection = self.sapapp.OpenConnection(connection_name, True)
                      ^^^^^^^^^^^^^^^^^^^^^^^^^^^^^^^^^^^^^^^^^^^^^^^^^
  File "<COMObject <unknown>>", line 2, in OpenConnection
pywintypes.com_error: (-2147352567, 'Exception occurred.', (1000, 'saplogon', 'SAP Logon connection entry not found', None, 0, 0), None)

During handling of the above exception, another exception occurred:

Traceback (most recent call last):
  File "C:\RobotFramework\sap_testing\Tests\Resource\CustomSapGuiLibrary.py", line 489, in open_connection
    raise ValueError(message)
ValueError: Cannot open connection '', please check connection name.

During handling of the above exception, another exception occurred:

Traceback (most recent call last):
  File "C:\RobotFramework\sap_testing\Execution\Access_Data.py", line 58, in get_data
    field_value = eval(command)
                  ^^^^^^^^^^^^^
  File "<string>", line 1, in <module>
AttributeError: module 'Data.Symphony.Dev' has no attribute 'connection'. Did you mean: 'sap_connection'?

